<?xml version="1.0"?>
<robot xmlns:xacro="http://www.ros.org/wiki/xacro" name="rain_arm">
    <xacro:property name="PI" value="3.14159"/>
    <xacro:property name="effort" value="30"/>
    <xacro:property name="velocity" value="10"/>
    
    
    <link name="world"/>

    <link name="base_link">
        <visual>
            <origin xyz="-0.5 -0.5 0.0" rpy="0.0 0.0 0.0"/>
            
            <geometry>
                <mesh filename="package://rain_arm_description/meshes/basement.STL" scale="0.01 0.01 0.01"/>
            </geometry>
        </visual>
    </link>    
    <joint name="world_base_link" type="fixed">
        <parent link="world"/>
        <child link="base_link"/>
        <origin xyz="0.0 0.0 0.0" rpy="0.0 0.0 0.0"/>
    </joint>

    <link name="base_plate">
        <visual>
            
            <origin xyz="-0.39 -0.39 -0.56" rpy="0.0 0.0 0.0"/>
            <geometry>
                <mesh filename="package://rain_arm_description/meshes/base_plate.STL" scale="0.01 0.01 0.01"/>
            </geometry>
        </visual>
    </link>

    <joint name="base_link_base_plate" type="revolute">
        <parent link="base_link"/>
        <child link="base_plate"/>
        <axis xyz="0.0 0.0 1"/>
        <origin xyz="0.0 0.0 0.307" rpy="0.0 0.0 0.0"/>
        <limit lower="-${PI/2}" upper="${PI/2}" effort="${effort}" velocity="${velocity}"/>
        
    </joint>

    <link name="forward_drive_arm">
        <visual>
            <origin rpy="0.0 -${PI/2} ${PI/2}" xyz="0.19 0.06 -0.08"/>
            
            <geometry>
                <mesh filename="package://rain_arm_description/meshes/forward_drive_arm.STL" scale="0.01 0.01 0.01"/>
            </geometry>
        </visual>
    </link>

    <joint name="base_plate_forward_drive_arm" type="revolute">
        <parent link="base_plate"/>
        <child link="forward_drive_arm"/>
        <origin xyz="-0.02 0.0 0.35" rpy="0.0 0.0 0.0"/>
        <axis xyz="1.0 0.0 0.0"/>
        <limit lower="-${PI/2}" upper="${PI/2}" effort="${effort}" velocity="${velocity}"/>
    </joint>


    <link name="horizontal_arm">
        <visual>
            <origin rpy="${PI/2} 0.0 ${PI/2}" xyz="-0.03 -0.4 -0.06"/>
            
            <geometry>
                <mesh filename="package://rain_arm_description/meshes/horizontal_arm.STL" scale="0.01 0.01 0.01"/>
            </geometry>
        </visual>
    </link>

    <joint name="forward_drive_arm_horizontal_arm" type="revolute">
        <parent link="forward_drive_arm"/>
        <child link="horizontal_arm"/>
        <limit lower="-${PI/2}" upper="${PI/2}" effort="${effort}" velocity="${velocity}"/>
        <axis xyz="1.0 0.0 0.0"/>
        <origin xyz="0.0 0.0 0.8" rpy="0.0 0.0 0.0"/>
    </joint>

    <link name="claw_base">
        <visual>
            <origin xyz="0.0 -0.05 -0.15" rpy="0.0 0.0 ${PI/2}"/>
            <geometry>
                <mesh filename="package://rain_arm_description/meshes/claw_support.STL" scale="0.01 0.01 0.01"/> 
            </geometry>
        </visual>
    </link>

        <joint name="horizontal_arm_claw_base" type="fixed">
            <parent link="horizontal_arm"/>
            <child link="claw_base"/>
            <origin xyz="0.0 0.82 0.0" rpy="0.0 0.0 0.0"/>
        </joint>

        <link name="gripper_right">
            <visual>
                <origin xyz="-0.1 0.5 -0.1" rpy="0.0 0.0 -${PI/2}"/>
                <geometry>
                    <mesh filename="package://rain_arm_description/meshes/right_finger.STL" scale="0.01 0.01 0.01"/>
                </geometry>
            </visual>
        </link>

        <link name="gripper_left">
            <visual>
                <origin xyz="-0.04 0.5 -0.1" rpy="0.0 0.0 -${PI/2}"/>
                <geometry>
                    <mesh filename="package://rain_arm_description/meshes/left_finger.STL" scale="0.01 0.01 0.01"/>
                </geometry>
            </visual>
        </link>
        
        
    <joint name="claw_base_gripper_right" type="revolute">
        <parent link="claw_base"/>
        <child link="gripper_right"/>
        <axis xyz="0.0 0.0 1.0"/>
        <origin xyz="-0.04 0.13 -0.1" rpy="0.0 0.0 0.0"/>  
        <limit lower="-${PI/2}" upper="0.0" effort="${effort}" velocity="${velocity}"/>

    </joint>

    <joint name="claw_base_gripper_left" type="revolute">
        <parent link="claw_base"/>
        <child link="gripper_left"/>
        <axis xyz="0.0 0.0 1.0"/>
        <origin xyz="-0.22 0.13 -0.1" rpy="0.0 0.0 0.0"/>  
        <mimic joint = "claw_base_gripper_right" multiplier = "-1"/>
        <limit lower="0.0" upper="${PI/2}" effort="${effort}" velocity="${velocity}"/>
    </joint>


</robot>