<?xml version="1.0"?>
<robot xmlns:xacro="http://www.ros.org/wiki/xacro" name="rain_arm">
    <xacro:property name="PI" value="3.14159"/>
    <xacro:property name="effort" value="30"/>
    <xacro:property name="velocity" value="10"/>
    
    <link name="world"/>

    <link name="base_link">
        <visual>
            <origin xyz="-0.5 -0.5 0.0" rpy="0.0 0.0 0.0"/>
            
            <geometry>
                <mesh filename="package://rain_arm_description/meshes/basement.STL" scale="0.01 0.01 0.01"/>
            </geometry>
        </visual>
    </link>    
    <joint name="world_base_link" type="fixed">
        <parent link="world"/>
        <child link="base_link"/>
        <origin xyz="0.0 0.0 0.0" rpy="0.0 0.0 0.0"/>
    </joint>

    <link name="base_plate">
        <visual>
            <origin xyz="-0.39 -0.39 -0.56" rpy="0.0 0.0 0.0"/>
            <geometry>
                <mesh filename="package://rain_arm_description/meshes/-.STL" scale="0.01 0.01 0.01"/>
            </geometry>
        </visual>
    </link>

    <joint name="base_link_base_plate" type="revolute">
        <parent link="base_link"/>
        <child link="base_plate"/>
        <axis xyz="0.0 0.0 1"/>
        <origin xyz="0.0 0.0 0.307" rpy="0.0 0.0 0.0"/>
        <limit lower="-${PI/2}" upper="${PI/2}" effort="${effort}" velocity="${velocity}"/>
        
    </joint>
    
</robot>